try {
    // Produce a ref error 
    myFunction(); 
} catch(err) {
    console.log(err.message)
} finally {
    
}